2023-10-01 00:41:53,911 - __main__ - ERROR - Erro ao inserir: 'Chave já existe na base de dados'
2023-10-01 00:42:17,227 - __main__ - ERROR - Falha ao enviar o webhook: HTTPConnectionPool(host='127.0.0.1', port=5000): Max retries exceeded with url: /webhook (Caused by NewConnectionError('<urllib3.connection.HTTPConnection object at 0x7fdf431e6b90>: Failed to establish a new connection: [Errno 111] Connection refused'))
2023-10-01 00:42:48,319 - __main__ - INFO - Webhook enviado com sucesso.
2023-10-01 01:02:50,492 - __main__ - INFO - Webhook enviado com sucesso.
2023-10-01 01:10:25,546 - __main__ - ERROR - Erro ao inserir: 'Chave já existe na base de dados'
2023-10-01 01:10:53,193 - __main__ - INFO - Webhook enviado com sucesso.
2023-10-01 01:12:02,984 - __main__ - INFO - Webhook enviado com sucesso.
2023-10-01 01:12:02,987 - __main__ - ERROR - Erro ao inserir: 'Chave já existe na base de dados'
2023-10-01 01:30:41,290 - __main__ - INFO - Dados exportados para dados_produtos.json com sucesso.
